[2025-06-14T10:29:43.718+0000] {local_task_job_runner.py:120} INFO - ::group::Pre task execution logs
[2025-06-14T10:29:43.742+0000] {taskinstance.py:2076} INFO - Dependencies all met for dep_context=non-requeueable deps ti=<TaskInstance: lp_yolov8_pipeline.prepare_pretrained_model scheduled__2025-06-14T09:30:00+00:00 [queued]>
[2025-06-14T10:29:43.752+0000] {taskinstance.py:2076} INFO - Dependencies all met for dep_context=requeueable deps ti=<TaskInstance: lp_yolov8_pipeline.prepare_pretrained_model scheduled__2025-06-14T09:30:00+00:00 [queued]>
[2025-06-14T10:29:43.753+0000] {taskinstance.py:2306} INFO - Starting attempt 2 of 2
[2025-06-14T10:29:43.766+0000] {taskinstance.py:2330} INFO - Executing <Task(PythonOperator): prepare_pretrained_model> on 2025-06-14 09:30:00+00:00
[2025-06-14T10:29:43.776+0000] {standard_task_runner.py:63} INFO - Started process 183 to run task
[2025-06-14T10:29:43.779+0000] {standard_task_runner.py:90} INFO - Running: ['***', 'tasks', 'run', 'lp_yolov8_pipeline', 'prepare_pretrained_model', 'scheduled__2025-06-14T09:30:00+00:00', '--job-id', '69', '--raw', '--subdir', 'DAGS_FOLDER/main.py', '--cfg-path', '/tmp/tmpeyq0rb31']
[2025-06-14T10:29:43.781+0000] {standard_task_runner.py:91} INFO - Job 69: Subtask prepare_pretrained_model
[2025-06-14T10:29:43.834+0000] {task_command.py:426} INFO - Running <TaskInstance: lp_yolov8_pipeline.prepare_pretrained_model scheduled__2025-06-14T09:30:00+00:00 [running]> on host 693466fafeae
[2025-06-14T10:29:43.932+0000] {taskinstance.py:2648} INFO - Exporting env vars: AIRFLOW_CTX_DAG_OWNER='***' AIRFLOW_CTX_DAG_ID='lp_yolov8_pipeline' AIRFLOW_CTX_TASK_ID='prepare_pretrained_model' AIRFLOW_CTX_EXECUTION_DATE='2025-06-14T09:30:00+00:00' AIRFLOW_CTX_TRY_NUMBER='2' AIRFLOW_CTX_DAG_RUN_ID='scheduled__2025-06-14T09:30:00+00:00'
[2025-06-14T10:29:43.934+0000] {taskinstance.py:430} INFO - ::endgroup::
[2025-06-14T10:29:44.174+0000] {logging_mixin.py:188} WARNING - 2025/06/14 10:29:44 WARNING mlflow.utils.git_utils: Failed to import Git (the Git executable is probably not on your PATH), so Git SHA is not available. Error: Failed to initialize: Bad git executable.
The git executable must be specified in one of the following ways:
    - be included in your $PATH
    - be set via $GIT_PYTHON_GIT_EXECUTABLE
    - explicitly set via git.refresh(<full-path-to-git-executable>)

All git commands will error until this is rectified.

This initial message can be silenced or aggravated in the future by setting the
$GIT_PYTHON_REFRESH environment variable. Use one of the following values:
    - quiet|q|silence|s|silent|none|n|0: for no message or exception
    - warn|w|warning|log|l|1: for a warning message (logging level CRITICAL, displayed by default)
    - error|e|exception|raise|r|2: for a raised exception

Example:
    export GIT_PYTHON_REFRESH=quiet
[2025-06-14T10:29:44.951+0000] {logging_mixin.py:188} INFO - Device: CPU
[2025-06-14T10:29:48.388+0000] {logging_mixin.py:188} WARNING - train: Scanning /opt/***/app/src/dataset/train/labels.cache... 381 images, 0 backgrounds, 0 corrupt: 100%|##########| 381/381 [00:00<?, ?it/s]
[2025-06-14T10:29:48.390+0000] {logging_mixin.py:188} WARNING - train: Scanning /opt/***/app/src/dataset/train/labels.cache... 381 images, 0 backgrounds, 0 corrupt: 100%|##########| 381/381 [00:00<?, ?it/s]
[2025-06-14T10:29:48.418+0000] {logging_mixin.py:188} WARNING - /home/***/.local/lib/python3.10/site-packages/torch/utils/data/dataloader.py:665 UserWarning: 'pin_memory' argument is set as true but no accelerator is found, then device pinned memory won't be used.
[2025-06-14T10:29:48.450+0000] {logging_mixin.py:188} WARNING - val: Scanning /opt/***/app/src/dataset/valid/labels.cache... 109 images, 0 backgrounds, 0 corrupt: 100%|##########| 109/109 [00:00<?, ?it/s]
[2025-06-14T10:29:48.451+0000] {logging_mixin.py:188} WARNING - val: Scanning /opt/***/app/src/dataset/valid/labels.cache... 109 images, 0 backgrounds, 0 corrupt: 100%|##########| 109/109 [00:00<?, ?it/s]
[2025-06-14T10:29:48.462+0000] {logging_mixin.py:188} WARNING - /home/***/.local/lib/python3.10/site-packages/torch/utils/data/dataloader.py:665 UserWarning: 'pin_memory' argument is set as true but no accelerator is found, then device pinned memory won't be used.
[2025-06-14T10:29:58.268+0000] {logging_mixin.py:188} WARNING -   0%|          | 0/24 [00:00<?, ?it/s]
[2025-06-14T10:34:34.094+0000] {local_task_job_runner.py:240} INFO - Task exited with return code -9
[2025-06-14T10:34:35.539+0000] {taskinstance.py:3503} INFO - 0 downstream tasks scheduled from follow-on schedule check
[2025-06-14T10:34:49.362+0000] {local_task_job_runner.py:222} INFO - ::endgroup::
