[2025-06-14T07:29:41.445+0000] {local_task_job_runner.py:120} INFO - ::group::Pre task execution logs
[2025-06-14T07:29:42.011+0000] {taskinstance.py:2076} INFO - Dependencies all met for dep_context=non-requeueable deps ti=<TaskInstance: lp_yolov8_pipeline.prepare_pretrained_model scheduled__2025-06-13T15:00:00+00:00 [queued]>
[2025-06-14T07:29:42.081+0000] {taskinstance.py:2076} INFO - Dependencies all met for dep_context=requeueable deps ti=<TaskInstance: lp_yolov8_pipeline.prepare_pretrained_model scheduled__2025-06-13T15:00:00+00:00 [queued]>
[2025-06-14T07:29:42.082+0000] {taskinstance.py:2306} INFO - Starting attempt 2 of 2
[2025-06-14T07:29:42.212+0000] {taskinstance.py:2330} INFO - Executing <Task(PythonOperator): prepare_pretrained_model> on 2025-06-13 15:00:00+00:00
[2025-06-14T07:29:42.288+0000] {standard_task_runner.py:63} INFO - Started process 466 to run task
[2025-06-14T07:29:42.386+0000] {standard_task_runner.py:90} INFO - Running: ['***', 'tasks', 'run', 'lp_yolov8_pipeline', 'prepare_pretrained_model', 'scheduled__2025-06-13T15:00:00+00:00', '--job-id', '53', '--raw', '--subdir', 'DAGS_FOLDER/main.py', '--cfg-path', '/tmp/tmpof6olc7h']
[2025-06-14T07:29:42.483+0000] {standard_task_runner.py:91} INFO - Job 53: Subtask prepare_pretrained_model
[2025-06-14T07:29:42.664+0000] {task_command.py:426} INFO - Running <TaskInstance: lp_yolov8_pipeline.prepare_pretrained_model scheduled__2025-06-13T15:00:00+00:00 [running]> on host 62fa818faa21
[2025-06-14T07:29:43.033+0000] {taskinstance.py:2648} INFO - Exporting env vars: AIRFLOW_CTX_DAG_OWNER='***' AIRFLOW_CTX_DAG_ID='lp_yolov8_pipeline' AIRFLOW_CTX_TASK_ID='prepare_pretrained_model' AIRFLOW_CTX_EXECUTION_DATE='2025-06-13T15:00:00+00:00' AIRFLOW_CTX_TRY_NUMBER='2' AIRFLOW_CTX_DAG_RUN_ID='scheduled__2025-06-13T15:00:00+00:00'
[2025-06-14T07:29:43.038+0000] {taskinstance.py:430} INFO - ::endgroup::
[2025-06-14T07:29:45.149+0000] {logging_mixin.py:188} WARNING - 2025/06/14 07:29:45 WARNING mlflow.utils.git_utils: Failed to import Git (the Git executable is probably not on your PATH), so Git SHA is not available. Error: Failed to initialize: Bad git executable.
The git executable must be specified in one of the following ways:
    - be included in your $PATH
    - be set via $GIT_PYTHON_GIT_EXECUTABLE
    - explicitly set via git.refresh(<full-path-to-git-executable>)

All git commands will error until this is rectified.

This initial message can be silenced or aggravated in the future by setting the
$GIT_PYTHON_REFRESH environment variable. Use one of the following values:
    - quiet|q|silence|s|silent|none|n|0: for no message or exception
    - warn|w|warning|log|l|1: for a warning message (logging level CRITICAL, displayed by default)
    - error|e|exception|raise|r|2: for a raised exception

Example:
    export GIT_PYTHON_REFRESH=quiet
[2025-06-14T07:29:48.828+0000] {logging_mixin.py:188} INFO - Device: CPU
[2025-06-14T07:30:01.737+0000] {logging_mixin.py:188} WARNING - train: Scanning /opt/***/app/src/dataset/train/labels.cache... 381 images, 0 backgrounds, 0 corrupt: 100%|##########| 381/381 [00:00<?, ?it/s]
[2025-06-14T07:30:01.739+0000] {logging_mixin.py:188} WARNING - train: Scanning /opt/***/app/src/dataset/train/labels.cache... 381 images, 0 backgrounds, 0 corrupt: 100%|##########| 381/381 [00:00<?, ?it/s]
[2025-06-14T07:30:01.912+0000] {logging_mixin.py:188} WARNING - /home/***/.local/lib/python3.10/site-packages/torch/utils/data/dataloader.py:665 UserWarning: 'pin_memory' argument is set as true but no accelerator is found, then device pinned memory won't be used.
[2025-06-14T07:30:02.545+0000] {logging_mixin.py:188} WARNING - val: Scanning /opt/***/app/src/dataset/valid/labels.cache... 109 images, 0 backgrounds, 0 corrupt: 100%|##########| 109/109 [00:00<?, ?it/s]
[2025-06-14T07:30:02.587+0000] {logging_mixin.py:188} WARNING - val: Scanning /opt/***/app/src/dataset/valid/labels.cache... 109 images, 0 backgrounds, 0 corrupt: 100%|##########| 109/109 [00:00<?, ?it/s]
[2025-06-14T07:30:02.797+0000] {logging_mixin.py:188} WARNING - /home/***/.local/lib/python3.10/site-packages/torch/utils/data/dataloader.py:665 UserWarning: 'pin_memory' argument is set as true but no accelerator is found, then device pinned memory won't be used.
[2025-06-14T07:31:57.446+0000] {job.py:218} ERROR - Job heartbeat got an exception
Traceback (most recent call last):
  File "/home/airflow/.local/lib/python3.10/site-packages/sqlalchemy/engine/base.py", line 3371, in _wrap_pool_connect
    return fn()
  File "/home/airflow/.local/lib/python3.10/site-packages/sqlalchemy/pool/base.py", line 327, in connect
    return _ConnectionFairy._checkout(self)
  File "/home/airflow/.local/lib/python3.10/site-packages/sqlalchemy/pool/base.py", line 894, in _checkout
    fairy = _ConnectionRecord.checkout(pool)
  File "/home/airflow/.local/lib/python3.10/site-packages/sqlalchemy/pool/base.py", line 493, in checkout
    rec = pool._do_get()
  File "/home/airflow/.local/lib/python3.10/site-packages/sqlalchemy/pool/impl.py", line 256, in _do_get
    return self._create_connection()
  File "/home/airflow/.local/lib/python3.10/site-packages/sqlalchemy/pool/base.py", line 273, in _create_connection
    return _ConnectionRecord(self)
  File "/home/airflow/.local/lib/python3.10/site-packages/sqlalchemy/pool/base.py", line 388, in __init__
    self.__connect()
  File "/home/airflow/.local/lib/python3.10/site-packages/sqlalchemy/pool/base.py", line 690, in __connect
    with util.safe_reraise():
  File "/home/airflow/.local/lib/python3.10/site-packages/sqlalchemy/util/langhelpers.py", line 70, in __exit__
    compat.raise_(
  File "/home/airflow/.local/lib/python3.10/site-packages/sqlalchemy/util/compat.py", line 211, in raise_
    raise exception
  File "/home/airflow/.local/lib/python3.10/site-packages/sqlalchemy/pool/base.py", line 686, in __connect
    self.dbapi_connection = connection = pool._invoke_creator(self)
  File "/home/airflow/.local/lib/python3.10/site-packages/sqlalchemy/engine/create.py", line 574, in connect
    return dialect.connect(*cargs, **cparams)
  File "/home/airflow/.local/lib/python3.10/site-packages/sqlalchemy/engine/default.py", line 598, in connect
    return self.dbapi.connect(*cargs, **cparams)
  File "/home/airflow/.local/lib/python3.10/site-packages/psycopg2/__init__.py", line 122, in connect
    conn = _connect(dsn, connection_factory=connection_factory, **kwasync)
psycopg2.OperationalError: could not translate host name "postgres" to address: Temporary failure in name resolution


The above exception was the direct cause of the following exception:

Traceback (most recent call last):
  File "/home/airflow/.local/lib/python3.10/site-packages/airflow/jobs/job.py", line 192, in heartbeat
    self._merge_from(Job._fetch_from_db(self, session))
  File "/home/airflow/.local/lib/python3.10/site-packages/airflow/api_internal/internal_api_call.py", line 115, in wrapper
    return func(*args, **kwargs)
  File "/home/airflow/.local/lib/python3.10/site-packages/airflow/utils/session.py", line 76, in wrapper
    return func(*args, **kwargs)
  File "/home/airflow/.local/lib/python3.10/site-packages/airflow/utils/retries.py", line 89, in wrapped_function
    for attempt in run_with_db_retries(max_retries=retries, logger=logger, **retry_kwargs):
  File "/home/airflow/.local/lib/python3.10/site-packages/tenacity/__init__.py", line 435, in __iter__
    do = self.iter(retry_state=retry_state)
  File "/home/airflow/.local/lib/python3.10/site-packages/tenacity/__init__.py", line 368, in iter
    result = action(retry_state)
  File "/home/airflow/.local/lib/python3.10/site-packages/tenacity/__init__.py", line 410, in exc_check
    raise retry_exc.reraise()
  File "/home/airflow/.local/lib/python3.10/site-packages/tenacity/__init__.py", line 183, in reraise
    raise self.last_attempt.result()
  File "/usr/local/lib/python3.10/concurrent/futures/_base.py", line 451, in result
    return self.__get_result()
  File "/usr/local/lib/python3.10/concurrent/futures/_base.py", line 403, in __get_result
    raise self._exception
  File "/home/airflow/.local/lib/python3.10/site-packages/airflow/utils/retries.py", line 98, in wrapped_function
    return func(*args, **kwargs)
  File "/home/airflow/.local/lib/python3.10/site-packages/airflow/jobs/job.py", line 316, in _fetch_from_db
    session.merge(job)
  File "/home/airflow/.local/lib/python3.10/site-packages/sqlalchemy/orm/session.py", line 3056, in merge
    return self._merge(
  File "/home/airflow/.local/lib/python3.10/site-packages/sqlalchemy/orm/session.py", line 3136, in _merge
    merged = self.get(
  File "/home/airflow/.local/lib/python3.10/site-packages/sqlalchemy/orm/session.py", line 2853, in get
    return self._get_impl(
  File "/home/airflow/.local/lib/python3.10/site-packages/sqlalchemy/orm/session.py", line 2975, in _get_impl
    return db_load_fn(
  File "/home/airflow/.local/lib/python3.10/site-packages/sqlalchemy/orm/loading.py", line 530, in load_on_pk_identity
    session.execute(
  File "/home/airflow/.local/lib/python3.10/site-packages/sqlalchemy/orm/session.py", line 1716, in execute
    conn = self._connection_for_bind(bind)
  File "/home/airflow/.local/lib/python3.10/site-packages/sqlalchemy/orm/session.py", line 1555, in _connection_for_bind
    return self._transaction._connection_for_bind(
  File "/home/airflow/.local/lib/python3.10/site-packages/sqlalchemy/orm/session.py", line 750, in _connection_for_bind
    conn = bind.connect()
  File "/home/airflow/.local/lib/python3.10/site-packages/sqlalchemy/future/engine.py", line 412, in connect
    return super(Engine, self).connect()
  File "/home/airflow/.local/lib/python3.10/site-packages/sqlalchemy/engine/base.py", line 3325, in connect
    return self._connection_cls(self, close_with_result=close_with_result)
  File "/home/airflow/.local/lib/python3.10/site-packages/sqlalchemy/engine/base.py", line 96, in __init__
    else engine.raw_connection()
  File "/home/airflow/.local/lib/python3.10/site-packages/sqlalchemy/engine/base.py", line 3404, in raw_connection
    return self._wrap_pool_connect(self.pool.connect, _connection)
  File "/home/airflow/.local/lib/python3.10/site-packages/sqlalchemy/engine/base.py", line 3374, in _wrap_pool_connect
    Connection._handle_dbapi_exception_noconnection(
  File "/home/airflow/.local/lib/python3.10/site-packages/sqlalchemy/engine/base.py", line 2208, in _handle_dbapi_exception_noconnection
    util.raise_(
  File "/home/airflow/.local/lib/python3.10/site-packages/sqlalchemy/util/compat.py", line 211, in raise_
    raise exception
  File "/home/airflow/.local/lib/python3.10/site-packages/sqlalchemy/engine/base.py", line 3371, in _wrap_pool_connect
    return fn()
  File "/home/airflow/.local/lib/python3.10/site-packages/sqlalchemy/pool/base.py", line 327, in connect
    return _ConnectionFairy._checkout(self)
  File "/home/airflow/.local/lib/python3.10/site-packages/sqlalchemy/pool/base.py", line 894, in _checkout
    fairy = _ConnectionRecord.checkout(pool)
  File "/home/airflow/.local/lib/python3.10/site-packages/sqlalchemy/pool/base.py", line 493, in checkout
    rec = pool._do_get()
  File "/home/airflow/.local/lib/python3.10/site-packages/sqlalchemy/pool/impl.py", line 256, in _do_get
    return self._create_connection()
  File "/home/airflow/.local/lib/python3.10/site-packages/sqlalchemy/pool/base.py", line 273, in _create_connection
    return _ConnectionRecord(self)
  File "/home/airflow/.local/lib/python3.10/site-packages/sqlalchemy/pool/base.py", line 388, in __init__
    self.__connect()
  File "/home/airflow/.local/lib/python3.10/site-packages/sqlalchemy/pool/base.py", line 690, in __connect
    with util.safe_reraise():
  File "/home/airflow/.local/lib/python3.10/site-packages/sqlalchemy/util/langhelpers.py", line 70, in __exit__
    compat.raise_(
  File "/home/airflow/.local/lib/python3.10/site-packages/sqlalchemy/util/compat.py", line 211, in raise_
    raise exception
  File "/home/airflow/.local/lib/python3.10/site-packages/sqlalchemy/pool/base.py", line 686, in __connect
    self.dbapi_connection = connection = pool._invoke_creator(self)
  File "/home/airflow/.local/lib/python3.10/site-packages/sqlalchemy/engine/create.py", line 574, in connect
    return dialect.connect(*cargs, **cparams)
  File "/home/airflow/.local/lib/python3.10/site-packages/sqlalchemy/engine/default.py", line 598, in connect
    return self.dbapi.connect(*cargs, **cparams)
  File "/home/airflow/.local/lib/python3.10/site-packages/psycopg2/__init__.py", line 122, in connect
    conn = _connect(dsn, connection_factory=connection_factory, **kwasync)
sqlalchemy.exc.OperationalError: (psycopg2.OperationalError) could not translate host name "postgres" to address: Temporary failure in name resolution

(Background on this error at: https://sqlalche.me/e/14/e3q8)
[2025-06-14T07:32:03.585+0000] {job.py:226} ERROR - Job heartbeat failed with error. Scheduler is in unhealthy state
[2025-06-14T07:32:51.087+0000] {logging_mixin.py:188} WARNING -   0%|          | 0/24 [00:00<?, ?it/s]
[2025-06-14T07:40:11.478+0000] {logging_mixin.py:188} WARNING -         1/1         0G      1.434      3.931      1.556         53        640:   0%|          | 0/24 [07:20<?, ?it/s]
[2025-06-14T07:40:11.703+0000] {logging_mixin.py:188} WARNING -         1/1         0G      1.434      3.931      1.556         53        640:   4%|4         | 1/24 [07:20<2:48:54, 440.61s/it]
[2025-06-14T07:45:29.627+0000] {logging_mixin.py:188} WARNING -         1/1         0G       1.38      3.756      1.449         44        640:   4%|4         | 1/24 [12:38<2:48:54, 440.61s/it]
[2025-06-14T07:45:29.692+0000] {logging_mixin.py:188} WARNING -         1/1         0G       1.38      3.756      1.449         44        640:   8%|8         | 2/24 [12:38<2:15:06, 368.48s/it]
[2025-06-14T07:47:19.556+0000] {job.py:226} ERROR - Job heartbeat failed with error. Scheduler is in unhealthy state
[2025-06-14T07:49:57.707+0000] {job.py:226} ERROR - Job heartbeat failed with error. Scheduler is in unhealthy state
[2025-06-14T07:50:20.942+0000] {logging_mixin.py:188} WARNING -         1/1         0G      1.404      3.745      1.447         59        640:   8%|8         | 2/24 [17:29<2:15:06, 368.48s/it]
[2025-06-14T07:50:20.998+0000] {logging_mixin.py:188} WARNING -         1/1         0G      1.404      3.745      1.447         59        640:  12%|#2        | 3/24 [17:29<1:56:38, 333.24s/it]
[2025-06-14T07:58:39.041+0000] {job.py:226} ERROR - Job heartbeat failed with error. Scheduler is in unhealthy state
[2025-06-14T07:59:00.022+0000] {logging_mixin.py:188} WARNING -         1/1         0G      1.384      3.722      1.432         53        640:  12%|#2        | 3/24 [26:08<1:56:38, 333.24s/it]
[2025-06-14T07:59:00.145+0000] {logging_mixin.py:188} WARNING -         1/1         0G      1.384      3.722      1.432         53        640:  17%|#6        | 4/24 [26:09<2:15:32, 406.63s/it]
[2025-06-14T08:01:39.684+0000] {job.py:226} ERROR - Job heartbeat failed with error. Scheduler is in unhealthy state
[2025-06-14T08:04:36.268+0000] {logging_mixin.py:188} WARNING -         1/1         0G      1.329      3.686      1.401         56        640:  17%|#6        | 4/24 [31:45<2:15:32, 406.63s/it]
[2025-06-14T08:04:36.323+0000] {logging_mixin.py:188} WARNING -         1/1         0G      1.329      3.686      1.401         56        640:  21%|##        | 5/24 [31:45<2:00:43, 381.23s/it]
[2025-06-14T08:07:03.169+0000] {job.py:226} ERROR - Job heartbeat failed with error. Scheduler is in unhealthy state
[2025-06-14T08:09:22.191+0000] {local_task_job_runner.py:310} WARNING - State of this instance has been externally set to None. Terminating instance.
[2025-06-14T08:09:26.233+0000] {local_task_job_runner.py:222} INFO - ::endgroup::
[2025-06-14T08:09:26.508+0000] {process_utils.py:132} INFO - Sending 15 to group 466. PIDs of all processes in the group: [466]
[2025-06-14T08:09:26.534+0000] {process_utils.py:87} INFO - Sending the signal 15 to group 466
[2025-06-14T08:10:26.972+0000] {process_utils.py:150} WARNING - process psutil.Process(pid=466, name='airflow task ru', status='disk-sleep', started='07:29:41') did not respond to SIGTERM. Trying SIGKILL
[2025-06-14T08:10:31.397+0000] {process_utils.py:87} INFO - Sending the signal 9 to group 466
[2025-06-14T08:10:34.776+0000] {process_utils.py:80} INFO - Process psutil.Process(pid=466, name='airflow task ru', status='terminated', exitcode=<Negsignal.SIGKILL: -9>, started='07:29:41') (466) terminated with exit code -9
[2025-06-14T08:10:36.504+0000] {standard_task_runner.py:178} ERROR - Job 53 was killed before it finished (likely due to running out of memory)
