[2025-06-14T07:23:51.411+0000] {local_task_job_runner.py:120} INFO - ::group::Pre task execution logs
[2025-06-14T07:23:51.483+0000] {taskinstance.py:2076} INFO - Dependencies all met for dep_context=non-requeueable deps ti=<TaskInstance: lp_yolov8_pipeline.prepare_pretrained_model scheduled__2025-06-13T15:00:00+00:00 [queued]>
[2025-06-14T07:23:51.895+0000] {taskinstance.py:2076} INFO - Dependencies all met for dep_context=requeueable deps ti=<TaskInstance: lp_yolov8_pipeline.prepare_pretrained_model scheduled__2025-06-13T15:00:00+00:00 [queued]>
[2025-06-14T07:23:51.896+0000] {taskinstance.py:2306} INFO - Starting attempt 1 of 2
[2025-06-14T07:23:51.923+0000] {taskinstance.py:2330} INFO - Executing <Task(PythonOperator): prepare_pretrained_model> on 2025-06-13 15:00:00+00:00
[2025-06-14T07:23:51.940+0000] {standard_task_runner.py:63} INFO - Started process 263 to run task
[2025-06-14T07:23:52.024+0000] {standard_task_runner.py:90} INFO - Running: ['***', 'tasks', 'run', 'lp_yolov8_pipeline', 'prepare_pretrained_model', 'scheduled__2025-06-13T15:00:00+00:00', '--job-id', '50', '--raw', '--subdir', 'DAGS_FOLDER/main.py', '--cfg-path', '/tmp/tmpjfpjl6na']
[2025-06-14T07:23:52.080+0000] {standard_task_runner.py:91} INFO - Job 50: Subtask prepare_pretrained_model
[2025-06-14T07:23:52.851+0000] {task_command.py:426} INFO - Running <TaskInstance: lp_yolov8_pipeline.prepare_pretrained_model scheduled__2025-06-13T15:00:00+00:00 [running]> on host 62fa818faa21
[2025-06-14T07:23:53.291+0000] {taskinstance.py:2648} INFO - Exporting env vars: AIRFLOW_CTX_DAG_OWNER='***' AIRFLOW_CTX_DAG_ID='lp_yolov8_pipeline' AIRFLOW_CTX_TASK_ID='prepare_pretrained_model' AIRFLOW_CTX_EXECUTION_DATE='2025-06-13T15:00:00+00:00' AIRFLOW_CTX_TRY_NUMBER='1' AIRFLOW_CTX_DAG_RUN_ID='scheduled__2025-06-13T15:00:00+00:00'
[2025-06-14T07:23:53.295+0000] {taskinstance.py:430} INFO - ::endgroup::
[2025-06-14T07:23:53.770+0000] {logging_mixin.py:188} WARNING - 2025/06/14 07:23:53 INFO mlflow.tracking.fluent: Experiment with name 'YOLOv8n_Finetune' does not exist. Creating a new experiment.
[2025-06-14T07:23:55.910+0000] {logging_mixin.py:188} WARNING - 2025/06/14 07:23:55 WARNING mlflow.utils.git_utils: Failed to import Git (the Git executable is probably not on your PATH), so Git SHA is not available. Error: Failed to initialize: Bad git executable.
The git executable must be specified in one of the following ways:
    - be included in your $PATH
    - be set via $GIT_PYTHON_GIT_EXECUTABLE
    - explicitly set via git.refresh(<full-path-to-git-executable>)

All git commands will error until this is rectified.

This initial message can be silenced or aggravated in the future by setting the
$GIT_PYTHON_REFRESH environment variable. Use one of the following values:
    - quiet|q|silence|s|silent|none|n|0: for no message or exception
    - warn|w|warning|log|l|1: for a warning message (logging level CRITICAL, displayed by default)
    - error|e|exception|raise|r|2: for a raised exception

Example:
    export GIT_PYTHON_REFRESH=quiet
[2025-06-14T07:24:08.044+0000] {logging_mixin.py:188} WARNING -   0%|          | 0.00/6.25M [00:00<?, ?B/s]
[2025-06-14T07:24:08.148+0000] {logging_mixin.py:188} WARNING -  12%|#2        | 768k/6.25M [00:00<00:00, 7.63MB/s]
[2025-06-14T07:24:08.458+0000] {logging_mixin.py:188} WARNING -  24%|##4       | 1.50M/6.25M [00:00<00:01, 3.50MB/s]
[2025-06-14T07:24:08.580+0000] {logging_mixin.py:188} WARNING -  38%|###8      | 2.38M/6.25M [00:00<00:00, 4.75MB/s]
[2025-06-14T07:24:08.762+0000] {logging_mixin.py:188} WARNING -  48%|####8     | 3.00M/6.25M [00:00<00:00, 4.29MB/s]
[2025-06-14T07:24:08.902+0000] {logging_mixin.py:188} WARNING -  56%|#####6    | 3.50M/6.25M [00:00<00:00, 4.13MB/s]
[2025-06-14T07:24:09.099+0000] {logging_mixin.py:188} WARNING -  70%|#######   | 4.38M/6.25M [00:01<00:00, 4.33MB/s]
[2025-06-14T07:24:09.213+0000] {logging_mixin.py:188} WARNING -  78%|#######8  | 4.88M/6.25M [00:01<00:00, 4.39MB/s]
[2025-06-14T07:24:09.353+0000] {logging_mixin.py:188} WARNING -  88%|########8 | 5.50M/6.25M [00:01<00:00, 4.48MB/s]
[2025-06-14T07:24:09.427+0000] {logging_mixin.py:188} WARNING - 100%|##########| 6.25M/6.25M [00:01<00:00, 4.74MB/s]
[2025-06-14T07:24:09.797+0000] {logging_mixin.py:188} INFO - Device: CPU
[2025-06-14T07:24:14.182+0000] {logging_mixin.py:188} INFO - 🏃 View run initial_training at: http://mlflow_server:5000/#/experiments/139258394477041911/runs/2446fe457b1e473683992c35a9f7caf7
[2025-06-14T07:24:14.206+0000] {logging_mixin.py:188} INFO - 🧪 View experiment at: http://mlflow_server:5000/#/experiments/139258394477041911
[2025-06-14T07:24:16.510+0000] {taskinstance.py:441} INFO - ::group::Post task execution logs
[2025-06-14T07:24:16.515+0000] {taskinstance.py:2905} ERROR - Task failed with exception
Traceback (most recent call last):
  File "/home/airflow/.local/lib/python3.10/site-packages/ultralytics/engine/trainer.py", line 607, in get_dataset
    data = check_det_dataset(self.args.data)
  File "/home/airflow/.local/lib/python3.10/site-packages/ultralytics/data/utils.py", line 463, in check_det_dataset
    raise FileNotFoundError(m)
FileNotFoundError: Dataset '/opt/***/app/src/data.yaml' images not found, missing path '/opt/***/app/src/dataset/valid/images'
Note dataset download directory is '/opt/***/datasets'. You can update this in '/home/***/.config/Ultralytics/settings.json'

The above exception was the direct cause of the following exception:

Traceback (most recent call last):
  File "/home/airflow/.local/lib/python3.10/site-packages/airflow/models/taskinstance.py", line 465, in _execute_task
    result = _execute_callable(context=context, **execute_callable_kwargs)
  File "/home/airflow/.local/lib/python3.10/site-packages/airflow/models/taskinstance.py", line 432, in _execute_callable
    return execute_callable(context=context, **execute_callable_kwargs)
  File "/home/airflow/.local/lib/python3.10/site-packages/airflow/models/baseoperator.py", line 401, in wrapper
    return func(self, *args, **kwargs)
  File "/home/airflow/.local/lib/python3.10/site-packages/airflow/operators/python.py", line 235, in execute
    return_value = self.execute_callable()
  File "/home/airflow/.local/lib/python3.10/site-packages/airflow/operators/python.py", line 252, in execute_callable
    return self.python_callable(*self.op_args, **self.op_kwargs)
  File "/opt/airflow/dags/main.py", line 70, in prepare_pretrained_model
    model_name, config, metrics = train(
  File "/opt/airflow/app/src/train.py", line 55, in train
    results = model.train(
  File "/home/airflow/.local/lib/python3.10/site-packages/ultralytics/engine/model.py", line 791, in train
    self.trainer = (trainer or self._smart_load("trainer"))(overrides=args, _callbacks=self.callbacks)
  File "/home/airflow/.local/lib/python3.10/site-packages/ultralytics/engine/trainer.py", line 153, in __init__
    self.data = self.get_dataset()
  File "/home/airflow/.local/lib/python3.10/site-packages/ultralytics/engine/trainer.py", line 611, in get_dataset
    raise RuntimeError(emojis(f"Dataset '{clean_url(self.args.data)}' error ❌ {e}")) from e
RuntimeError: Dataset '/opt/***/app/src/data.yaml' error ❌ Dataset '/opt/***/app/src/data.yaml' images not found, missing path '/opt/***/app/src/dataset/valid/images'
Note dataset download directory is '/opt/***/datasets'. You can update this in '/home/***/.config/Ultralytics/settings.json'
[2025-06-14T07:24:16.563+0000] {taskinstance.py:1206} INFO - Marking task as UP_FOR_RETRY. dag_id=lp_yolov8_pipeline, task_id=prepare_pretrained_model, run_id=scheduled__2025-06-13T15:00:00+00:00, execution_date=20250613T150000, start_date=20250614T072351, end_date=20250614T072416
[2025-06-14T07:24:16.607+0000] {standard_task_runner.py:110} ERROR - Failed to execute job 50 for task prepare_pretrained_model (Dataset '/opt/***/app/src/data.yaml' error ❌ Dataset '/opt/***/app/src/data.yaml' images not found, missing path '/opt/***/app/src/dataset/valid/images'
Note dataset download directory is '/opt/***/datasets'. You can update this in '/home/***/.config/Ultralytics/settings.json'; 263)
[2025-06-14T07:24:16.659+0000] {local_task_job_runner.py:240} INFO - Task exited with return code 1
[2025-06-14T07:24:16.691+0000] {taskinstance.py:3503} INFO - 0 downstream tasks scheduled from follow-on schedule check
[2025-06-14T07:24:16.822+0000] {local_task_job_runner.py:222} INFO - ::endgroup::
