[2025-06-14T07:25:09.266+0000] {local_task_job_runner.py:120} INFO - ::group::Pre task execution logs
[2025-06-14T07:25:09.292+0000] {taskinstance.py:2076} INFO - Dependencies all met for dep_context=non-requeueable deps ti=<TaskInstance: lp_yolov8_pipeline.prepare_pretrained_model scheduled__2025-06-14T06:30:00+00:00 [queued]>
[2025-06-14T07:25:09.302+0000] {taskinstance.py:2076} INFO - Dependencies all met for dep_context=requeueable deps ti=<TaskInstance: lp_yolov8_pipeline.prepare_pretrained_model scheduled__2025-06-14T06:30:00+00:00 [queued]>
[2025-06-14T07:25:09.303+0000] {taskinstance.py:2306} INFO - Starting attempt 1 of 2
[2025-06-14T07:25:09.315+0000] {taskinstance.py:2330} INFO - Executing <Task(PythonOperator): prepare_pretrained_model> on 2025-06-14 06:30:00+00:00
[2025-06-14T07:25:09.325+0000] {standard_task_runner.py:63} INFO - Started process 356 to run task
[2025-06-14T07:25:09.328+0000] {standard_task_runner.py:90} INFO - Running: ['***', 'tasks', 'run', 'lp_yolov8_pipeline', 'prepare_pretrained_model', 'scheduled__2025-06-14T06:30:00+00:00', '--job-id', '52', '--raw', '--subdir', 'DAGS_FOLDER/main.py', '--cfg-path', '/tmp/tmpbt7nqbfh']
[2025-06-14T07:25:09.330+0000] {standard_task_runner.py:91} INFO - Job 52: Subtask prepare_pretrained_model
[2025-06-14T07:25:09.371+0000] {task_command.py:426} INFO - Running <TaskInstance: lp_yolov8_pipeline.prepare_pretrained_model scheduled__2025-06-14T06:30:00+00:00 [running]> on host 62fa818faa21
[2025-06-14T07:25:09.460+0000] {taskinstance.py:2648} INFO - Exporting env vars: AIRFLOW_CTX_DAG_OWNER='***' AIRFLOW_CTX_DAG_ID='lp_yolov8_pipeline' AIRFLOW_CTX_TASK_ID='prepare_pretrained_model' AIRFLOW_CTX_EXECUTION_DATE='2025-06-14T06:30:00+00:00' AIRFLOW_CTX_TRY_NUMBER='1' AIRFLOW_CTX_DAG_RUN_ID='scheduled__2025-06-14T06:30:00+00:00'
[2025-06-14T07:25:09.462+0000] {taskinstance.py:430} INFO - ::endgroup::
[2025-06-14T07:25:09.607+0000] {logging_mixin.py:188} WARNING - 2025/06/14 07:25:09 WARNING mlflow.utils.git_utils: Failed to import Git (the Git executable is probably not on your PATH), so Git SHA is not available. Error: Failed to initialize: Bad git executable.
The git executable must be specified in one of the following ways:
    - be included in your $PATH
    - be set via $GIT_PYTHON_GIT_EXECUTABLE
    - explicitly set via git.refresh(<full-path-to-git-executable>)

All git commands will error until this is rectified.

This initial message can be silenced or aggravated in the future by setting the
$GIT_PYTHON_REFRESH environment variable. Use one of the following values:
    - quiet|q|silence|s|silent|none|n|0: for no message or exception
    - warn|w|warning|log|l|1: for a warning message (logging level CRITICAL, displayed by default)
    - error|e|exception|raise|r|2: for a raised exception

Example:
    export GIT_PYTHON_REFRESH=quiet
[2025-06-14T07:25:10.251+0000] {logging_mixin.py:188} INFO - Device: CPU
[2025-06-14T07:25:12.763+0000] {font_manager.py:1639} INFO - generated new fontManager
[2025-06-14T07:25:15.216+0000] {logging_mixin.py:188} WARNING -   0%|          | 0.00/755k [00:00<?, ?B/s]
[2025-06-14T07:25:15.323+0000] {logging_mixin.py:188} WARNING -  34%|###3      | 256k/755k [00:00<00:00, 2.48MB/s]
[2025-06-14T07:25:15.401+0000] {logging_mixin.py:188} WARNING - 100%|##########| 755k/755k [00:00<00:00, 4.22MB/s]
[2025-06-14T07:25:15.809+0000] {logging_mixin.py:188} WARNING - train: Scanning /opt/***/app/src/dataset/train/labels...:   0%|          | 0/381 [00:00<?, ?it/s]
[2025-06-14T07:25:16.208+0000] {logging_mixin.py:188} WARNING - train: Scanning /opt/***/app/src/dataset/train/labels... 3 images, 0 backgrounds, 0 corrupt:   1%|          | 3/381 [00:00<00:50,  7.55it/s]
[2025-06-14T07:25:16.340+0000] {logging_mixin.py:188} WARNING - train: Scanning /opt/***/app/src/dataset/train/labels... 17 images, 0 backgrounds, 0 corrupt:   4%|4         | 17/381 [00:00<00:09, 39.49it/s]
[2025-06-14T07:25:16.438+0000] {logging_mixin.py:188} WARNING - train: Scanning /opt/***/app/src/dataset/train/labels... 207 images, 0 backgrounds, 0 corrupt:  54%|#####4    | 207/381 [00:00<00:00, 521.79it/s]
[2025-06-14T07:25:16.543+0000] {logging_mixin.py:188} WARNING - train: Scanning /opt/***/app/src/dataset/train/labels... 351 images, 0 backgrounds, 0 corrupt:  92%|#########2| 351/381 [00:00<00:00, 760.79it/s]
[2025-06-14T07:25:16.572+0000] {logging_mixin.py:188} WARNING - train: Scanning /opt/***/app/src/dataset/train/labels... 381 images, 0 backgrounds, 0 corrupt: 100%|##########| 381/381 [00:00<00:00, 500.44it/s]
[2025-06-14T07:25:17.653+0000] {logging_mixin.py:188} WARNING - /home/***/.local/lib/python3.10/site-packages/torch/utils/data/dataloader.py:665 UserWarning: 'pin_memory' argument is set as true but no accelerator is found, then device pinned memory won't be used.
[2025-06-14T07:25:17.663+0000] {logging_mixin.py:188} WARNING - val: Scanning /opt/***/app/src/dataset/valid/labels...:   0%|          | 0/109 [00:00<?, ?it/s]
[2025-06-14T07:25:17.737+0000] {logging_mixin.py:188} WARNING - val: Scanning /opt/***/app/src/dataset/valid/labels... 109 images, 0 backgrounds, 0 corrupt: 100%|##########| 109/109 [00:00<00:00, 1498.94it/s]
[2025-06-14T07:25:17.855+0000] {logging_mixin.py:188} WARNING - /home/***/.local/lib/python3.10/site-packages/torch/utils/data/dataloader.py:665 UserWarning: 'pin_memory' argument is set as true but no accelerator is found, then device pinned memory won't be used.
[2025-06-14T07:25:27.029+0000] {logging_mixin.py:188} WARNING -   0%|          | 0/24 [00:00<?, ?it/s]
[2025-06-14T07:29:38.225+0000] {logging_mixin.py:188} WARNING -         1/1         0G      1.434      3.931      1.556         53        640:   0%|          | 0/24 [04:11<?, ?it/s]
[2025-06-14T07:29:38.392+0000] {logging_mixin.py:188} WARNING -         1/1         0G      1.434      3.931      1.556         53        640:   4%|4         | 1/24 [04:11<1:36:21, 251.36s/it]
[2025-06-14T07:31:57.638+0000] {job.py:218} ERROR - Job heartbeat got an exception
Traceback (most recent call last):
  File "/home/airflow/.local/lib/python3.10/site-packages/sqlalchemy/engine/base.py", line 3371, in _wrap_pool_connect
    return fn()
  File "/home/airflow/.local/lib/python3.10/site-packages/sqlalchemy/pool/base.py", line 327, in connect
    return _ConnectionFairy._checkout(self)
  File "/home/airflow/.local/lib/python3.10/site-packages/sqlalchemy/pool/base.py", line 894, in _checkout
    fairy = _ConnectionRecord.checkout(pool)
  File "/home/airflow/.local/lib/python3.10/site-packages/sqlalchemy/pool/base.py", line 493, in checkout
    rec = pool._do_get()
  File "/home/airflow/.local/lib/python3.10/site-packages/sqlalchemy/pool/impl.py", line 256, in _do_get
    return self._create_connection()
  File "/home/airflow/.local/lib/python3.10/site-packages/sqlalchemy/pool/base.py", line 273, in _create_connection
    return _ConnectionRecord(self)
  File "/home/airflow/.local/lib/python3.10/site-packages/sqlalchemy/pool/base.py", line 388, in __init__
    self.__connect()
  File "/home/airflow/.local/lib/python3.10/site-packages/sqlalchemy/pool/base.py", line 690, in __connect
    with util.safe_reraise():
  File "/home/airflow/.local/lib/python3.10/site-packages/sqlalchemy/util/langhelpers.py", line 70, in __exit__
    compat.raise_(
  File "/home/airflow/.local/lib/python3.10/site-packages/sqlalchemy/util/compat.py", line 211, in raise_
    raise exception
  File "/home/airflow/.local/lib/python3.10/site-packages/sqlalchemy/pool/base.py", line 686, in __connect
    self.dbapi_connection = connection = pool._invoke_creator(self)
  File "/home/airflow/.local/lib/python3.10/site-packages/sqlalchemy/engine/create.py", line 574, in connect
    return dialect.connect(*cargs, **cparams)
  File "/home/airflow/.local/lib/python3.10/site-packages/sqlalchemy/engine/default.py", line 598, in connect
    return self.dbapi.connect(*cargs, **cparams)
  File "/home/airflow/.local/lib/python3.10/site-packages/psycopg2/__init__.py", line 122, in connect
    conn = _connect(dsn, connection_factory=connection_factory, **kwasync)
psycopg2.OperationalError: could not translate host name "postgres" to address: Temporary failure in name resolution


The above exception was the direct cause of the following exception:

Traceback (most recent call last):
  File "/home/airflow/.local/lib/python3.10/site-packages/airflow/jobs/job.py", line 192, in heartbeat
    self._merge_from(Job._fetch_from_db(self, session))
  File "/home/airflow/.local/lib/python3.10/site-packages/airflow/api_internal/internal_api_call.py", line 115, in wrapper
    return func(*args, **kwargs)
  File "/home/airflow/.local/lib/python3.10/site-packages/airflow/utils/session.py", line 76, in wrapper
    return func(*args, **kwargs)
  File "/home/airflow/.local/lib/python3.10/site-packages/airflow/utils/retries.py", line 89, in wrapped_function
    for attempt in run_with_db_retries(max_retries=retries, logger=logger, **retry_kwargs):
  File "/home/airflow/.local/lib/python3.10/site-packages/tenacity/__init__.py", line 435, in __iter__
    do = self.iter(retry_state=retry_state)
  File "/home/airflow/.local/lib/python3.10/site-packages/tenacity/__init__.py", line 368, in iter
    result = action(retry_state)
  File "/home/airflow/.local/lib/python3.10/site-packages/tenacity/__init__.py", line 410, in exc_check
    raise retry_exc.reraise()
  File "/home/airflow/.local/lib/python3.10/site-packages/tenacity/__init__.py", line 183, in reraise
    raise self.last_attempt.result()
  File "/usr/local/lib/python3.10/concurrent/futures/_base.py", line 451, in result
    return self.__get_result()
  File "/usr/local/lib/python3.10/concurrent/futures/_base.py", line 403, in __get_result
    raise self._exception
  File "/home/airflow/.local/lib/python3.10/site-packages/airflow/utils/retries.py", line 98, in wrapped_function
    return func(*args, **kwargs)
  File "/home/airflow/.local/lib/python3.10/site-packages/airflow/jobs/job.py", line 316, in _fetch_from_db
    session.merge(job)
  File "/home/airflow/.local/lib/python3.10/site-packages/sqlalchemy/orm/session.py", line 3056, in merge
    return self._merge(
  File "/home/airflow/.local/lib/python3.10/site-packages/sqlalchemy/orm/session.py", line 3136, in _merge
    merged = self.get(
  File "/home/airflow/.local/lib/python3.10/site-packages/sqlalchemy/orm/session.py", line 2853, in get
    return self._get_impl(
  File "/home/airflow/.local/lib/python3.10/site-packages/sqlalchemy/orm/session.py", line 2975, in _get_impl
    return db_load_fn(
  File "/home/airflow/.local/lib/python3.10/site-packages/sqlalchemy/orm/loading.py", line 530, in load_on_pk_identity
    session.execute(
  File "/home/airflow/.local/lib/python3.10/site-packages/sqlalchemy/orm/session.py", line 1716, in execute
    conn = self._connection_for_bind(bind)
  File "/home/airflow/.local/lib/python3.10/site-packages/sqlalchemy/orm/session.py", line 1555, in _connection_for_bind
    return self._transaction._connection_for_bind(
  File "/home/airflow/.local/lib/python3.10/site-packages/sqlalchemy/orm/session.py", line 750, in _connection_for_bind
    conn = bind.connect()
  File "/home/airflow/.local/lib/python3.10/site-packages/sqlalchemy/future/engine.py", line 412, in connect
    return super(Engine, self).connect()
  File "/home/airflow/.local/lib/python3.10/site-packages/sqlalchemy/engine/base.py", line 3325, in connect
    return self._connection_cls(self, close_with_result=close_with_result)
  File "/home/airflow/.local/lib/python3.10/site-packages/sqlalchemy/engine/base.py", line 96, in __init__
    else engine.raw_connection()
  File "/home/airflow/.local/lib/python3.10/site-packages/sqlalchemy/engine/base.py", line 3404, in raw_connection
    return self._wrap_pool_connect(self.pool.connect, _connection)
  File "/home/airflow/.local/lib/python3.10/site-packages/sqlalchemy/engine/base.py", line 3374, in _wrap_pool_connect
    Connection._handle_dbapi_exception_noconnection(
  File "/home/airflow/.local/lib/python3.10/site-packages/sqlalchemy/engine/base.py", line 2208, in _handle_dbapi_exception_noconnection
    util.raise_(
  File "/home/airflow/.local/lib/python3.10/site-packages/sqlalchemy/util/compat.py", line 211, in raise_
    raise exception
  File "/home/airflow/.local/lib/python3.10/site-packages/sqlalchemy/engine/base.py", line 3371, in _wrap_pool_connect
    return fn()
  File "/home/airflow/.local/lib/python3.10/site-packages/sqlalchemy/pool/base.py", line 327, in connect
    return _ConnectionFairy._checkout(self)
  File "/home/airflow/.local/lib/python3.10/site-packages/sqlalchemy/pool/base.py", line 894, in _checkout
    fairy = _ConnectionRecord.checkout(pool)
  File "/home/airflow/.local/lib/python3.10/site-packages/sqlalchemy/pool/base.py", line 493, in checkout
    rec = pool._do_get()
  File "/home/airflow/.local/lib/python3.10/site-packages/sqlalchemy/pool/impl.py", line 256, in _do_get
    return self._create_connection()
  File "/home/airflow/.local/lib/python3.10/site-packages/sqlalchemy/pool/base.py", line 273, in _create_connection
    return _ConnectionRecord(self)
  File "/home/airflow/.local/lib/python3.10/site-packages/sqlalchemy/pool/base.py", line 388, in __init__
    self.__connect()
  File "/home/airflow/.local/lib/python3.10/site-packages/sqlalchemy/pool/base.py", line 690, in __connect
    with util.safe_reraise():
  File "/home/airflow/.local/lib/python3.10/site-packages/sqlalchemy/util/langhelpers.py", line 70, in __exit__
    compat.raise_(
  File "/home/airflow/.local/lib/python3.10/site-packages/sqlalchemy/util/compat.py", line 211, in raise_
    raise exception
  File "/home/airflow/.local/lib/python3.10/site-packages/sqlalchemy/pool/base.py", line 686, in __connect
    self.dbapi_connection = connection = pool._invoke_creator(self)
  File "/home/airflow/.local/lib/python3.10/site-packages/sqlalchemy/engine/create.py", line 574, in connect
    return dialect.connect(*cargs, **cparams)
  File "/home/airflow/.local/lib/python3.10/site-packages/sqlalchemy/engine/default.py", line 598, in connect
    return self.dbapi.connect(*cargs, **cparams)
  File "/home/airflow/.local/lib/python3.10/site-packages/psycopg2/__init__.py", line 122, in connect
    conn = _connect(dsn, connection_factory=connection_factory, **kwasync)
sqlalchemy.exc.OperationalError: (psycopg2.OperationalError) could not translate host name "postgres" to address: Temporary failure in name resolution

(Background on this error at: https://sqlalche.me/e/14/e3q8)
[2025-06-14T07:32:11.314+0000] {job.py:226} ERROR - Job heartbeat failed with error. Scheduler is in unhealthy state
[2025-06-14T07:32:37.951+0000] {local_task_job_runner.py:240} INFO - Task exited with return code -9
[2025-06-14T07:32:39.883+0000] {taskinstance.py:3503} INFO - 0 downstream tasks scheduled from follow-on schedule check
[2025-06-14T07:32:39.888+0000] {local_task_job_runner.py:222} INFO - ::endgroup::
