[2025-06-14T08:13:37.272+0000] {local_task_job_runner.py:120} INFO - ::group::Pre task execution logs
[2025-06-14T08:13:37.387+0000] {taskinstance.py:2076} INFO - Dependencies all met for dep_context=non-requeueable deps ti=<TaskInstance: lp_yolov8_pipeline.prepare_pretrained_model scheduled__2025-06-14T07:30:00+00:00 [queued]>
[2025-06-14T08:13:37.413+0000] {taskinstance.py:2076} INFO - Dependencies all met for dep_context=requeueable deps ti=<TaskInstance: lp_yolov8_pipeline.prepare_pretrained_model scheduled__2025-06-14T07:30:00+00:00 [queued]>
[2025-06-14T08:13:37.413+0000] {taskinstance.py:2306} INFO - Starting attempt 1 of 2
[2025-06-14T08:13:37.442+0000] {taskinstance.py:2330} INFO - Executing <Task(PythonOperator): prepare_pretrained_model> on 2025-06-14 07:30:00+00:00
[2025-06-14T08:13:37.538+0000] {standard_task_runner.py:63} INFO - Started process 1227 to run task
[2025-06-14T08:13:37.607+0000] {standard_task_runner.py:90} INFO - Running: ['***', 'tasks', 'run', 'lp_yolov8_pipeline', 'prepare_pretrained_model', 'scheduled__2025-06-14T07:30:00+00:00', '--job-id', '58', '--raw', '--subdir', 'DAGS_FOLDER/main.py', '--cfg-path', '/tmp/tmppg2wetjg']
[2025-06-14T08:13:37.638+0000] {standard_task_runner.py:91} INFO - Job 58: Subtask prepare_pretrained_model
[2025-06-14T08:13:38.244+0000] {task_command.py:426} INFO - Running <TaskInstance: lp_yolov8_pipeline.prepare_pretrained_model scheduled__2025-06-14T07:30:00+00:00 [running]> on host 62fa818faa21
[2025-06-14T08:13:38.511+0000] {taskinstance.py:2648} INFO - Exporting env vars: AIRFLOW_CTX_DAG_OWNER='***' AIRFLOW_CTX_DAG_ID='lp_yolov8_pipeline' AIRFLOW_CTX_TASK_ID='prepare_pretrained_model' AIRFLOW_CTX_EXECUTION_DATE='2025-06-14T07:30:00+00:00' AIRFLOW_CTX_TRY_NUMBER='1' AIRFLOW_CTX_DAG_RUN_ID='scheduled__2025-06-14T07:30:00+00:00'
[2025-06-14T08:13:38.537+0000] {taskinstance.py:430} INFO - ::endgroup::
[2025-06-14T08:13:39.856+0000] {logging_mixin.py:188} WARNING - 2025/06/14 08:13:39 WARNING mlflow.utils.git_utils: Failed to import Git (the Git executable is probably not on your PATH), so Git SHA is not available. Error: Failed to initialize: Bad git executable.
The git executable must be specified in one of the following ways:
    - be included in your $PATH
    - be set via $GIT_PYTHON_GIT_EXECUTABLE
    - explicitly set via git.refresh(<full-path-to-git-executable>)

All git commands will error until this is rectified.

This initial message can be silenced or aggravated in the future by setting the
$GIT_PYTHON_REFRESH environment variable. Use one of the following values:
    - quiet|q|silence|s|silent|none|n|0: for no message or exception
    - warn|w|warning|log|l|1: for a warning message (logging level CRITICAL, displayed by default)
    - error|e|exception|raise|r|2: for a raised exception

Example:
    export GIT_PYTHON_REFRESH=quiet
[2025-06-14T08:13:41.156+0000] {logging_mixin.py:188} INFO - Device: CPU
[2025-06-14T08:13:47.553+0000] {logging_mixin.py:188} WARNING - train: Scanning /opt/***/app/src/dataset/train/labels.cache... 381 images, 0 backgrounds, 0 corrupt: 100%|##########| 381/381 [00:00<?, ?it/s]
[2025-06-14T08:13:47.565+0000] {logging_mixin.py:188} WARNING - train: Scanning /opt/***/app/src/dataset/train/labels.cache... 381 images, 0 backgrounds, 0 corrupt: 100%|##########| 381/381 [00:00<?, ?it/s]
[2025-06-14T08:13:47.604+0000] {logging_mixin.py:188} WARNING - /home/***/.local/lib/python3.10/site-packages/torch/utils/data/dataloader.py:665 UserWarning: 'pin_memory' argument is set as true but no accelerator is found, then device pinned memory won't be used.
[2025-06-14T08:13:47.697+0000] {logging_mixin.py:188} WARNING - val: Scanning /opt/***/app/src/dataset/valid/labels.cache... 109 images, 0 backgrounds, 0 corrupt: 100%|##########| 109/109 [00:00<?, ?it/s]
[2025-06-14T08:13:47.699+0000] {logging_mixin.py:188} WARNING - val: Scanning /opt/***/app/src/dataset/valid/labels.cache... 109 images, 0 backgrounds, 0 corrupt: 100%|##########| 109/109 [00:00<?, ?it/s]
[2025-06-14T08:13:47.707+0000] {logging_mixin.py:188} WARNING - /home/***/.local/lib/python3.10/site-packages/torch/utils/data/dataloader.py:665 UserWarning: 'pin_memory' argument is set as true but no accelerator is found, then device pinned memory won't be used.
[2025-06-14T08:13:59.709+0000] {logging_mixin.py:188} WARNING -   0%|          | 0/24 [00:00<?, ?it/s]
[2025-06-14T08:14:51.502+0000] {job.py:218} ERROR - Job heartbeat got an exception
Traceback (most recent call last):
  File "/home/airflow/.local/lib/python3.10/site-packages/sqlalchemy/engine/base.py", line 3371, in _wrap_pool_connect
    return fn()
  File "/home/airflow/.local/lib/python3.10/site-packages/sqlalchemy/pool/base.py", line 327, in connect
    return _ConnectionFairy._checkout(self)
  File "/home/airflow/.local/lib/python3.10/site-packages/sqlalchemy/pool/base.py", line 894, in _checkout
    fairy = _ConnectionRecord.checkout(pool)
  File "/home/airflow/.local/lib/python3.10/site-packages/sqlalchemy/pool/base.py", line 493, in checkout
    rec = pool._do_get()
  File "/home/airflow/.local/lib/python3.10/site-packages/sqlalchemy/pool/impl.py", line 256, in _do_get
    return self._create_connection()
  File "/home/airflow/.local/lib/python3.10/site-packages/sqlalchemy/pool/base.py", line 273, in _create_connection
    return _ConnectionRecord(self)
  File "/home/airflow/.local/lib/python3.10/site-packages/sqlalchemy/pool/base.py", line 388, in __init__
    self.__connect()
  File "/home/airflow/.local/lib/python3.10/site-packages/sqlalchemy/pool/base.py", line 690, in __connect
    with util.safe_reraise():
  File "/home/airflow/.local/lib/python3.10/site-packages/sqlalchemy/util/langhelpers.py", line 70, in __exit__
    compat.raise_(
  File "/home/airflow/.local/lib/python3.10/site-packages/sqlalchemy/util/compat.py", line 211, in raise_
    raise exception
  File "/home/airflow/.local/lib/python3.10/site-packages/sqlalchemy/pool/base.py", line 686, in __connect
    self.dbapi_connection = connection = pool._invoke_creator(self)
  File "/home/airflow/.local/lib/python3.10/site-packages/sqlalchemy/engine/create.py", line 574, in connect
    return dialect.connect(*cargs, **cparams)
  File "/home/airflow/.local/lib/python3.10/site-packages/sqlalchemy/engine/default.py", line 598, in connect
    return self.dbapi.connect(*cargs, **cparams)
  File "/home/airflow/.local/lib/python3.10/site-packages/psycopg2/__init__.py", line 122, in connect
    conn = _connect(dsn, connection_factory=connection_factory, **kwasync)
psycopg2.OperationalError: could not translate host name "postgres" to address: Temporary failure in name resolution


The above exception was the direct cause of the following exception:

Traceback (most recent call last):
  File "/home/airflow/.local/lib/python3.10/site-packages/airflow/jobs/job.py", line 192, in heartbeat
    self._merge_from(Job._fetch_from_db(self, session))
  File "/home/airflow/.local/lib/python3.10/site-packages/airflow/api_internal/internal_api_call.py", line 115, in wrapper
    return func(*args, **kwargs)
  File "/home/airflow/.local/lib/python3.10/site-packages/airflow/utils/session.py", line 76, in wrapper
    return func(*args, **kwargs)
  File "/home/airflow/.local/lib/python3.10/site-packages/airflow/utils/retries.py", line 89, in wrapped_function
    for attempt in run_with_db_retries(max_retries=retries, logger=logger, **retry_kwargs):
  File "/home/airflow/.local/lib/python3.10/site-packages/tenacity/__init__.py", line 435, in __iter__
    do = self.iter(retry_state=retry_state)
  File "/home/airflow/.local/lib/python3.10/site-packages/tenacity/__init__.py", line 368, in iter
    result = action(retry_state)
  File "/home/airflow/.local/lib/python3.10/site-packages/tenacity/__init__.py", line 410, in exc_check
    raise retry_exc.reraise()
  File "/home/airflow/.local/lib/python3.10/site-packages/tenacity/__init__.py", line 183, in reraise
    raise self.last_attempt.result()
  File "/usr/local/lib/python3.10/concurrent/futures/_base.py", line 451, in result
    return self.__get_result()
  File "/usr/local/lib/python3.10/concurrent/futures/_base.py", line 403, in __get_result
    raise self._exception
  File "/home/airflow/.local/lib/python3.10/site-packages/airflow/utils/retries.py", line 98, in wrapped_function
    return func(*args, **kwargs)
  File "/home/airflow/.local/lib/python3.10/site-packages/airflow/jobs/job.py", line 316, in _fetch_from_db
    session.merge(job)
  File "/home/airflow/.local/lib/python3.10/site-packages/sqlalchemy/orm/session.py", line 3056, in merge
    return self._merge(
  File "/home/airflow/.local/lib/python3.10/site-packages/sqlalchemy/orm/session.py", line 3136, in _merge
    merged = self.get(
  File "/home/airflow/.local/lib/python3.10/site-packages/sqlalchemy/orm/session.py", line 2853, in get
    return self._get_impl(
  File "/home/airflow/.local/lib/python3.10/site-packages/sqlalchemy/orm/session.py", line 2975, in _get_impl
    return db_load_fn(
  File "/home/airflow/.local/lib/python3.10/site-packages/sqlalchemy/orm/loading.py", line 530, in load_on_pk_identity
    session.execute(
  File "/home/airflow/.local/lib/python3.10/site-packages/sqlalchemy/orm/session.py", line 1716, in execute
    conn = self._connection_for_bind(bind)
  File "/home/airflow/.local/lib/python3.10/site-packages/sqlalchemy/orm/session.py", line 1555, in _connection_for_bind
    return self._transaction._connection_for_bind(
  File "/home/airflow/.local/lib/python3.10/site-packages/sqlalchemy/orm/session.py", line 750, in _connection_for_bind
    conn = bind.connect()
  File "/home/airflow/.local/lib/python3.10/site-packages/sqlalchemy/future/engine.py", line 412, in connect
    return super(Engine, self).connect()
  File "/home/airflow/.local/lib/python3.10/site-packages/sqlalchemy/engine/base.py", line 3325, in connect
    return self._connection_cls(self, close_with_result=close_with_result)
  File "/home/airflow/.local/lib/python3.10/site-packages/sqlalchemy/engine/base.py", line 96, in __init__
    else engine.raw_connection()
  File "/home/airflow/.local/lib/python3.10/site-packages/sqlalchemy/engine/base.py", line 3404, in raw_connection
    return self._wrap_pool_connect(self.pool.connect, _connection)
  File "/home/airflow/.local/lib/python3.10/site-packages/sqlalchemy/engine/base.py", line 3374, in _wrap_pool_connect
    Connection._handle_dbapi_exception_noconnection(
  File "/home/airflow/.local/lib/python3.10/site-packages/sqlalchemy/engine/base.py", line 2208, in _handle_dbapi_exception_noconnection
    util.raise_(
  File "/home/airflow/.local/lib/python3.10/site-packages/sqlalchemy/util/compat.py", line 211, in raise_
    raise exception
  File "/home/airflow/.local/lib/python3.10/site-packages/sqlalchemy/engine/base.py", line 3371, in _wrap_pool_connect
    return fn()
  File "/home/airflow/.local/lib/python3.10/site-packages/sqlalchemy/pool/base.py", line 327, in connect
    return _ConnectionFairy._checkout(self)
  File "/home/airflow/.local/lib/python3.10/site-packages/sqlalchemy/pool/base.py", line 894, in _checkout
    fairy = _ConnectionRecord.checkout(pool)
  File "/home/airflow/.local/lib/python3.10/site-packages/sqlalchemy/pool/base.py", line 493, in checkout
    rec = pool._do_get()
  File "/home/airflow/.local/lib/python3.10/site-packages/sqlalchemy/pool/impl.py", line 256, in _do_get
    return self._create_connection()
  File "/home/airflow/.local/lib/python3.10/site-packages/sqlalchemy/pool/base.py", line 273, in _create_connection
    return _ConnectionRecord(self)
  File "/home/airflow/.local/lib/python3.10/site-packages/sqlalchemy/pool/base.py", line 388, in __init__
    self.__connect()
  File "/home/airflow/.local/lib/python3.10/site-packages/sqlalchemy/pool/base.py", line 690, in __connect
    with util.safe_reraise():
  File "/home/airflow/.local/lib/python3.10/site-packages/sqlalchemy/util/langhelpers.py", line 70, in __exit__
    compat.raise_(
  File "/home/airflow/.local/lib/python3.10/site-packages/sqlalchemy/util/compat.py", line 211, in raise_
    raise exception
  File "/home/airflow/.local/lib/python3.10/site-packages/sqlalchemy/pool/base.py", line 686, in __connect
    self.dbapi_connection = connection = pool._invoke_creator(self)
  File "/home/airflow/.local/lib/python3.10/site-packages/sqlalchemy/engine/create.py", line 574, in connect
    return dialect.connect(*cargs, **cparams)
  File "/home/airflow/.local/lib/python3.10/site-packages/sqlalchemy/engine/default.py", line 598, in connect
    return self.dbapi.connect(*cargs, **cparams)
  File "/home/airflow/.local/lib/python3.10/site-packages/psycopg2/__init__.py", line 122, in connect
    conn = _connect(dsn, connection_factory=connection_factory, **kwasync)
sqlalchemy.exc.OperationalError: (psycopg2.OperationalError) could not translate host name "postgres" to address: Temporary failure in name resolution

(Background on this error at: https://sqlalche.me/e/14/e3q8)
[2025-06-14T08:15:09.909+0000] {job.py:226} ERROR - Job heartbeat failed with error. Scheduler is in unhealthy state
[2025-06-14T08:17:47.920+0000] {local_task_job_runner.py:310} WARNING - State of this instance has been externally set to None. Terminating instance.
[2025-06-14T08:17:48.179+0000] {local_task_job_runner.py:222} INFO - ::endgroup::
[2025-06-14T08:17:48.557+0000] {process_utils.py:132} INFO - Sending 15 to group 1227. PIDs of all processes in the group: [1227]
[2025-06-14T08:17:48.566+0000] {process_utils.py:87} INFO - Sending the signal 15 to group 1227
[2025-06-14T08:17:48.647+0000] {taskinstance.py:2611} ERROR - Received SIGTERM. Terminating subprocesses.
[2025-06-14T08:17:48.831+0000] {logging_mixin.py:188} WARNING -   0%|          | 0/24 [03:49<?, ?it/s]
[2025-06-14T08:17:50.328+0000] {logging_mixin.py:188} INFO - 🏃 View run initial_training at: http://mlflow_server:5000/#/experiments/139258394477041911/runs/67c708bddc144e489a50a85fd58c3fbc
[2025-06-14T08:17:50.330+0000] {logging_mixin.py:188} INFO - 🧪 View experiment at: http://mlflow_server:5000/#/experiments/139258394477041911
[2025-06-14T08:17:50.800+0000] {taskinstance.py:441} INFO - ::group::Post task execution logs
[2025-06-14T08:17:51.104+0000] {taskinstance.py:2905} ERROR - Task failed with exception
Traceback (most recent call last):
  File "/home/airflow/.local/lib/python3.10/site-packages/airflow/models/taskinstance.py", line 465, in _execute_task
    result = _execute_callable(context=context, **execute_callable_kwargs)
  File "/home/airflow/.local/lib/python3.10/site-packages/airflow/models/taskinstance.py", line 432, in _execute_callable
    return execute_callable(context=context, **execute_callable_kwargs)
  File "/home/airflow/.local/lib/python3.10/site-packages/airflow/models/baseoperator.py", line 401, in wrapper
    return func(self, *args, **kwargs)
  File "/home/airflow/.local/lib/python3.10/site-packages/airflow/operators/python.py", line 235, in execute
    return_value = self.execute_callable()
  File "/home/airflow/.local/lib/python3.10/site-packages/airflow/operators/python.py", line 252, in execute_callable
    return self.python_callable(*self.op_args, **self.op_kwargs)
  File "/opt/airflow/dags/main.py", line 70, in prepare_pretrained_model
    model_name, config, metrics = train(
  File "/opt/airflow/app/src/train.py", line 55, in train
    results = model.train(
  File "/home/airflow/.local/lib/python3.10/site-packages/ultralytics/engine/model.py", line 797, in train
    self.trainer.train()
  File "/home/airflow/.local/lib/python3.10/site-packages/ultralytics/engine/trainer.py", line 227, in train
    self._do_train(world_size)
  File "/home/airflow/.local/lib/python3.10/site-packages/ultralytics/engine/trainer.py", line 406, in _do_train
    loss, self.loss_items = self.model(batch)
  File "/home/airflow/.local/lib/python3.10/site-packages/torch/nn/modules/module.py", line 1751, in _wrapped_call_impl
    return self._call_impl(*args, **kwargs)
  File "/home/airflow/.local/lib/python3.10/site-packages/torch/nn/modules/module.py", line 1762, in _call_impl
    return forward_call(*args, **kwargs)
  File "/home/airflow/.local/lib/python3.10/site-packages/ultralytics/nn/tasks.py", line 137, in forward
    return self.loss(x, *args, **kwargs)
  File "/home/airflow/.local/lib/python3.10/site-packages/ultralytics/nn/tasks.py", line 336, in loss
    preds = self.forward(batch["img"]) if preds is None else preds
  File "/home/airflow/.local/lib/python3.10/site-packages/ultralytics/nn/tasks.py", line 138, in forward
    return self.predict(x, *args, **kwargs)
  File "/home/airflow/.local/lib/python3.10/site-packages/ultralytics/nn/tasks.py", line 156, in predict
    return self._predict_once(x, profile, visualize, embed)
  File "/home/airflow/.local/lib/python3.10/site-packages/ultralytics/nn/tasks.py", line 179, in _predict_once
    x = m(x)  # run
  File "/home/airflow/.local/lib/python3.10/site-packages/torch/nn/modules/module.py", line 1751, in _wrapped_call_impl
    return self._call_impl(*args, **kwargs)
  File "/home/airflow/.local/lib/python3.10/site-packages/torch/nn/modules/module.py", line 1762, in _call_impl
    return forward_call(*args, **kwargs)
  File "/home/airflow/.local/lib/python3.10/site-packages/ultralytics/nn/modules/block.py", line 319, in forward
    return self.cv2(torch.cat(y, 1))
  File "/home/airflow/.local/lib/python3.10/site-packages/torch/nn/modules/module.py", line 1751, in _wrapped_call_impl
    return self._call_impl(*args, **kwargs)
  File "/home/airflow/.local/lib/python3.10/site-packages/torch/nn/modules/module.py", line 1762, in _call_impl
    return forward_call(*args, **kwargs)
  File "/home/airflow/.local/lib/python3.10/site-packages/ultralytics/nn/modules/conv.py", line 80, in forward
    return self.act(self.bn(self.conv(x)))
  File "/home/airflow/.local/lib/python3.10/site-packages/torch/nn/modules/module.py", line 1751, in _wrapped_call_impl
    return self._call_impl(*args, **kwargs)
  File "/home/airflow/.local/lib/python3.10/site-packages/torch/nn/modules/module.py", line 1762, in _call_impl
    return forward_call(*args, **kwargs)
  File "/home/airflow/.local/lib/python3.10/site-packages/torch/nn/modules/activation.py", line 432, in forward
    return F.silu(input, inplace=self.inplace)
  File "/home/airflow/.local/lib/python3.10/site-packages/torch/nn/functional.py", line 2379, in silu
    return torch._C._nn.silu_(input)
  File "/home/airflow/.local/lib/python3.10/site-packages/airflow/models/taskinstance.py", line 2613, in signal_handler
    raise AirflowTaskTerminated("Task received SIGTERM signal")
airflow.exceptions.AirflowTaskTerminated: Task received SIGTERM signal
[2025-06-14T08:17:51.204+0000] {taskinstance.py:1206} INFO - Marking task as FAILED. dag_id=lp_yolov8_pipeline, task_id=prepare_pretrained_model, run_id=scheduled__2025-06-14T07:30:00+00:00, execution_date=20250614T073000, start_date=20250614T081337, end_date=20250614T081751
[2025-06-14T08:17:51.607+0000] {process_utils.py:80} INFO - Process psutil.Process(pid=1227, status='terminated', exitcode=2, started='08:13:36') (1227) terminated with exit code 2
